Workbook

Sheet Blad1
A1: Musea - Nederlandse benaming (Title) | B1: Musea - Franse benaming (Alternative Title) | C1: Provincie (location) | D1: Alle Thema's | E1: Geschiedenis en archeologie | F1: Wetenschap en technologie | G1: Mode | H1: Literatuur | I1: Architectuur | J1: Beeldende kunst | K1: Toegepaste kunst en design | M1: Shop | N1: Café | O1: Parking | P1: Restaurant | Q1: Algemene naam --> als geen NL naam dan FR | R1: Prijs | S1: Tijdelijk gesloten | T1: Tijdelijke tentoonstelling(en) | U1: Prijs incl. tijdelijke tentoonstelling | X1: # Museums | Y1: Average Price | Z1: Median
A2: Archeologisch museum van de Boven-Maas | B2: Musée archéologique de la Haute-Meuse | C2: Namen | D2: Geschiedenis en archeologie | E2: =If(IFERROR(SEARCH(E$1, $D2),0) >= 1, true,false) -> TRUE | F2: =If(IFERROR(SEARCH(F$1, $D2),0) >= 1, true,false) -> FALSE | G2: =If(IFERROR(SEARCH(G$1, $D2),0) >= 1, true,false) -> FALSE | H2: =If(IFERROR(SEARCH(H$1, $D2),0) >= 1, true,false) -> FALSE | I2: =If(IFERROR(SEARCH(I$1, $D2),0) >= 1, true,false) -> FALSE | J2: =If(IFERROR(SEARCH(J$1, $D2),0) >= 1, true,false) -> FALSE | K2: =If(IFERROR(SEARCH(K$1, $D2),0) >= 1, true,false) -> FALSE | M2: TRUE | N2: FALSE | O2: TRUE | P2: FALSE | Q2: =IF(ISBLANK(A2),B2,A2) -> Archeologisch museum van de Boven-Maas | R2: 3.5 | S2: FALSE | T2: FALSE | W2: Namen | X2: =COUNTIF(C:C, "Namen") -> 15 | Y2: =AVERAGEIF(C:C, "Namen",R:R) -> 5.9666667 | Z2: =MEDIAN(R2:R16) -> 6
A3: Citadel van Namen / Bezoekerscentrum Terra Nova en toeristentreintje | B3: =IFERROR(__xludf.DUMMYFUNCTION("SPLIT(A3, "" - "", FALSE,FALSE)"),"Citadel van Namen / Bezoekerscentrum Terra Nova en toeristentreintje") -> Citadel van Namen / Bezoekerscentrum Terra Nova en toeristentreintje | C3: Namen | D3: Geschiedenis en archeologie | E3: =If(IFERROR(SEARCH(E$1, $D3),0) >= 1, true,false) -> TRUE | F3: =If(IFERROR(SEARCH(F$1, $D3),0) >= 1, true,false) -> FALSE | G3: =If(IFERROR(SEARCH(G$1, $D3),0) >= 1, true,false) -> FALSE | H3: =If(IFERROR(SEARCH(H$1, $D3),0) >= 1, true,false) -> FALSE | I3: =If(IFERROR(SEARCH(I$1, $D3),0) >= 1, true,false) -> FALSE | J3: =If(IFERROR(SEARCH(J$1, $D3),0) >= 1, true,false) -> FALSE | K3: =If(IFERROR(SEARCH(K$1, $D3),0) >= 1, true,false) -> FALSE | M3: TRUE | N3: TRUE | O3: FALSE | P3: FALSE | Q3: =IF(ISBLANK(A3),B3,A3) -> Citadel van Namen / Bezoekerscentrum Terra Nova en toeristentreintje | R3: 6 | S3: FALSE | T3: FALSE | W3: West-Vlaanderen | X3: =COUNTIF(C:C, "West-Vlaanderen") -> 41 | Y3: =AVERAGEIF(C:C, "West-Vlaanderen",R:R) -> 9.1463415 | Z3: =MEDIAN(R17:R57) -> 9
A4: NAM-IP Computermuseum | B4: Computer Museum NAM-IP | C4: Namen | D4: Wetenschap en technologie | E4: =If(IFERROR(SEARCH(E$1, $D4),0) >= 1, true,false) -> FALSE | F4: =If(IFERROR(SEARCH(F$1, $D4),0) >= 1, true,false) -> TRUE | G4: =If(IFERROR(SEARCH(G$1, $D4),0) >= 1, true,false) -> FALSE | H4: =If(IFERROR(SEARCH(H$1, $D4),0) >= 1, true,false) -> FALSE | I4: =If(IFERROR(SEARCH(I$1, $D4),0) >= 1, true,false) -> FALSE | J4: =If(IFERROR(SEARCH(J$1, $D4),0) >= 1, true,false) -> FALSE | K4: =If(IFERROR(SEARCH(K$1, $D4),0) >= 1, true,false) -> FALSE | M4: TRUE | N4: TRUE | O4: TRUE | P4: FALSE | Q4: =IF(ISBLANK(A4),B4,A4) -> NAM-IP Computermuseum | R4: 8 | S4: FALSE | T4: FALSE | W4: Antwerpen | X4: 35 | Y4: =AVERAGE($R$58:$R$91) -> 9.25 | Z4: =MEDIAN($R$58:$R$91) -> 10
A5: Ecomuseum van de Viroin | B5: Écomusée du Viroin | C5: Namen | D5: Geschiedenis en archeologie | E5: =If(IFERROR(SEARCH(E$1, $D5),0) >= 1, true,false) -> TRUE | F5: =If(IFERROR(SEARCH(F$1, $D5),0) >= 1, true,false) -> FALSE | G5: =If(IFERROR(SEARCH(G$1, $D5),0) >= 1, true,false) -> FALSE | H5: =If(IFERROR(SEARCH(H$1, $D5),0) >= 1, true,false) -> FALSE | I5: =If(IFERROR(SEARCH(I$1, $D5),0) >= 1, true,false) -> FALSE | J5: =If(IFERROR(SEARCH(J$1, $D5),0) >= 1, true,false) -> FALSE | K5: =If(IFERROR(SEARCH(K$1, $D5),0) >= 1, true,false) -> FALSE | M5: TRUE | N5: FALSE | O5: FALSE | P5: FALSE | Q5: =IF(ISBLANK(A5),B5,A5) -> Ecomuseum van de Viroin | R5: 4 | S5: FALSE | T5: TRUE | U5: 4 | W5: Waals-Brabant | X5: 5 | Y5: =AVERAGE($R$93:$R$97) -> 8.8 | Z5: =MEDIAN($R$93:$R$97) -> 10
A6: Andenne Museum | B6: Espace Muséal d’Andenne | C6: Namen | D6: Toegepaste kunst en design, Geschiedenis en archeologie | E6: =If(IFERROR(SEARCH(E$1, $D6),0) >= 1, true,false) -> TRUE | F6: =If(IFERROR(SEARCH(F$1, $D6),0) >= 1, true,false) -> FALSE | G6: =If(IFERROR(SEARCH(G$1, $D6),0) >= 1, true,false) -> FALSE | H6: =If(IFERROR(SEARCH(H$1, $D6),0) >= 1, true,false) -> FALSE | I6: =If(IFERROR(SEARCH(I$1, $D6),0) >= 1, true,false) -> FALSE | J6: =If(IFERROR(SEARCH(J$1, $D6),0) >= 1, true,false) -> FALSE | K6: =If(IFERROR(SEARCH(K$1, $D6),0) >= 1, true,false) -> TRUE | M6: TRUE | N6: FALSE | O6: FALSE | P6: FALSE | Q6: =IF(ISBLANK(A6),B6,A6) -> Andenne Museum | R6: 10 | S6: FALSE | T6: FALSE | W6: Vlaams-Brabant | X6: 13 | Y6: =AVERAGE($R$98:$R$110) -> 8.1923077 | Z6: =MEDIAN($R$98:$R$110) -> 10
B7: Le Delta | C7: Namen | D7: Beeldende kunst | E7: =If(IFERROR(SEARCH(E$1, $D7),0) >= 1, true,false) -> FALSE | F7: =If(IFERROR(SEARCH(F$1, $D7),0) >= 1, true,false) -> FALSE | G7: =If(IFERROR(SEARCH(G$1, $D7),0) >= 1, true,false) -> FALSE | H7: =If(IFERROR(SEARCH(H$1, $D7),0) >= 1, true,false) -> FALSE | I7: =If(IFERROR(SEARCH(I$1, $D7),0) >= 1, true,false) -> FALSE | J7: =If(IFERROR(SEARCH(J$1, $D7),0) >= 1, true,false) -> TRUE | K7: =If(IFERROR(SEARCH(K$1, $D7),0) >= 1, true,false) -> FALSE | M7: TRUE | N7: FALSE | O7: FALSE | P7: TRUE | Q7: =IF(ISBLANK(A7),B7,A7) -> Le Delta | R7: 5 | S7: FALSE | T7: TRUE | U7: 5 | W7: Limburg | X7: =COUNTIF(C:C, "Limburg") -> 15 | Y7: =AVERAGEIF(C:C, "Limburg",R:R) -> 8.3333333 | Z7: =MEDIAN(R111,R125) -> 9
B8: Le Pavillon | C8: Namen | D8: Beeldende kunst, Wetenschap en technologie | E8: =If(IFERROR(SEARCH(E$1, $D8),0) >= 1, true,false) -> FALSE | F8: =If(IFERROR(SEARCH(F$1, $D8),0) >= 1, true,false) -> TRUE | G8: =If(IFERROR(SEARCH(G$1, $D8),0) >= 1, true,false) -> FALSE | H8: =If(IFERROR(SEARCH(H$1, $D8),0) >= 1, true,false) -> FALSE | I8: =If(IFERROR(SEARCH(I$1, $D8),0) >= 1, true,false) -> FALSE | J8: =If(IFERROR(SEARCH(J$1, $D8),0) >= 1, true,false) -> TRUE | K8: =If(IFERROR(SEARCH(K$1, $D8),0) >= 1, true,false) -> FALSE | M8: TRUE | N8: FALSE | O8: FALSE | P8: FALSE | Q8: =IF(ISBLANK(A8),B8,A8) -> Le Pavillon | R8: 10 | S8: FALSE | T8: TRUE | U8: 10 | W8: Luik | X8: =COUNTIF(C:C, "Luik") -> 19 | Y8: =AVERAGEIF(C:C, "Luik",R:R) -> 6.6315789 | Z8: =MEDIAN(R126,R144) -> 10.5
B9: Maison du patrimoine médiéval mosan | C9: Namen | D9: Geschiedenis en archeologie | E9: =If(IFERROR(SEARCH(E$1, $D9),0) >= 1, true,false) -> TRUE | F9: =If(IFERROR(SEARCH(F$1, $D9),0) >= 1, true,false) -> FALSE | G9: =If(IFERROR(SEARCH(G$1, $D9),0) >= 1, true,false) -> FALSE | H9: =If(IFERROR(SEARCH(H$1, $D9),0) >= 1, true,false) -> FALSE | I9: =If(IFERROR(SEARCH(I$1, $D9),0) >= 1, true,false) -> FALSE | J9: =If(IFERROR(SEARCH(J$1, $D9),0) >= 1, true,false) -> FALSE | K9: =If(IFERROR(SEARCH(K$1, $D9),0) >= 1, true,false) -> FALSE | M9: TRUE | N9: FALSE | O9: TRUE | P9: FALSE | Q9: =IF(ISBLANK(A9),B9,A9) -> Maison du patrimoine médiéval mosan | R9: 6 | S9: FALSE | T9: TRUE | U9: 6 | W9: Henegouwen | X9: =COUNTIF(C:C,"Henegouwen") -> 37 | Y9: =AVERAGEIF(C:C,"Henegouwen",R:R) -> 6.5405405 | Z9: =MEDIAN(R145:R181) -> 6
A10: Archeopark van Rochefort | B10: Malagne | Archéoparc de Rochefort | C10: Namen | D10: Geschiedenis en archeologie | E10: =If(IFERROR(SEARCH(E$1, $D10),0) >= 1, true,false) -> TRUE | F10: =If(IFERROR(SEARCH(F$1, $D10),0) >= 1, true,false) -> FALSE | G10: =If(IFERROR(SEARCH(G$1, $D10),0) >= 1, true,false) -> FALSE | H10: =If(IFERROR(SEARCH(H$1, $D10),0) >= 1, true,false) -> FALSE | I10: =If(IFERROR(SEARCH(I$1, $D10),0) >= 1, true,false) -> FALSE | J10: =If(IFERROR(SEARCH(J$1, $D10),0) >= 1, true,false) -> FALSE | K10: =If(IFERROR(SEARCH(K$1, $D10),0) >= 1, true,false) -> FALSE | M10: TRUE | N10: TRUE | O10: TRUE | P10: FALSE | Q10: =IF(ISBLANK(A10),B10,A10) -> Archeopark van Rochefort | R10: 8 | S10: FALSE | T10: FALSE | W10: Luxemburg | X10: =COUNTIF(C:C,"Luxemburg") -> 9 | Y10: =AVERAGEIF(C:C,"Luxemburg",R:R) -> 7.0555556 | Z10: =MEDIAN(R182,R190) -> 10.5
A11: MusAfrica Namen | B11: MusAfrica Namur | C11: Namen | D11: Toegepaste kunst en design, Geschiedenis en archeologie | E11: =If(IFERROR(SEARCH(E$1, $D11),0) >= 1, true,false) -> TRUE | F11: =If(IFERROR(SEARCH(F$1, $D11),0) >= 1, true,false) -> FALSE | G11: =If(IFERROR(SEARCH(G$1, $D11),0) >= 1, true,false) -> FALSE | H11: =If(IFERROR(SEARCH(H$1, $D11),0) >= 1, true,false) -> FALSE | I11: =If(IFERROR(SEARCH(I$1, $D11),0) >= 1, true,false) -> FALSE | J11: =If(IFERROR(SEARCH(J$1, $D11),0) >= 1, true,false) -> FALSE | K11: =If(IFERROR(SEARCH(K$1, $D11),0) >= 1, true,false) -> TRUE | M11: TRUE | N11: FALSE | O11: FALSE | P11: FALSE | Q11: =IF(ISBLANK(A11),B11,A11) -> MusAfrica Namen | R11: 8 | S11: FALSE | T11: FALSE | W11: Brussel | X11: =countif(C2:C261,"Brussel") -> 48 | Y11: =AVERAGE(R191:R238) -> 9.1875 | Z11: =MEDIAN(R191:R238) -> 10
A12: Aardbeimuseum | B12: Musée de la Fraise | C12: Namen | D12: Beeldende kunst, Geschiedenis en archeologie, Wetenschap en technologie | E12: =If(IFERROR(SEARCH(E$1, $D12),0) >= 1, true,false) -> TRUE | F12: =If(IFERROR(SEARCH(F$1, $D12),0) >= 1, true,false) -> TRUE | G12: =If(IFERROR(SEARCH(G$1, $D12),0) >= 1, true,false) -> FALSE | H12: =If(IFERROR(SEARCH(H$1, $D12),0) >= 1, true,false) -> FALSE | I12: =If(IFERROR(SEARCH(I$1, $D12),0) >= 1, true,false) -> FALSE | J12: =If(IFERROR(SEARCH(J$1, $D12),0) >= 1, true,false) -> TRUE | K12: =If(IFERROR(SEARCH(K$1, $D12),0) >= 1, true,false) -> FALSE | M12: TRUE | N12: FALSE | O12: FALSE | P12: FALSE | Q12: =IF(ISBLANK(A12),B12,A12) -> Aardbeimuseum | R12: 6 | S12: FALSE | T12: FALSE | W12: Oost-Vlaanderen | X12: =countif(C2:C261,"Oost-Vlaanderen") -> 23 | Y12: =AVERAGE(R239:R261) -> 8.5652174 | Z12: =MEDIAN(R239:R261) -> 9
B13: Musée du Malgré-Tout | C13: Namen | D13: Geschiedenis en archeologie | E13: =If(IFERROR(SEARCH(E$1, $D13),0) >= 1, true,false) -> TRUE | F13: =If(IFERROR(SEARCH(F$1, $D13),0) >= 1, true,false) -> FALSE | G13: =If(IFERROR(SEARCH(G$1, $D13),0) >= 1, true,false) -> FALSE | H13: =If(IFERROR(SEARCH(H$1, $D13),0) >= 1, true,false) -> FALSE | I13: =If(IFERROR(SEARCH(I$1, $D13),0) >= 1, true,false) -> FALSE | J13: =If(IFERROR(SEARCH(J$1, $D13),0) >= 1, true,false) -> FALSE | K13: =If(IFERROR(SEARCH(K$1, $D13),0) >= 1, true,false) -> FALSE | M13: TRUE | N13: FALSE | O13: FALSE | P13: FALSE | Q13: =IF(ISBLANK(A13),B13,A13) -> Musée du Malgré-Tout | R13: 5 | S13: FALSE | T13: FALSE
A14: Museum van het Klein Formaat | B14: Musée du Petit Format | C14: Namen | D14: Beeldende kunst | E14: =If(IFERROR(SEARCH(E$1, $D14),0) >= 1, true,false) -> FALSE | F14: =If(IFERROR(SEARCH(F$1, $D14),0) >= 1, true,false) -> FALSE | G14: =If(IFERROR(SEARCH(G$1, $D14),0) >= 1, true,false) -> FALSE | H14: =If(IFERROR(SEARCH(H$1, $D14),0) >= 1, true,false) -> FALSE | I14: =If(IFERROR(SEARCH(I$1, $D14),0) >= 1, true,false) -> FALSE | J14: =If(IFERROR(SEARCH(J$1, $D14),0) >= 1, true,false) -> TRUE | K14: =If(IFERROR(SEARCH(K$1, $D14),0) >= 1, true,false) -> FALSE | M14: TRUE | N14: FALSE | O14: FALSE | P14: FALSE | Q14: =IF(ISBLANK(A14),B14,A14) -> Museum van het Klein Formaat | R14: 5 | S14: FALSE | T14: TRUE | U14: 5
A15: Félicien Rops Museum | B15: Musée Félicien Rops | C15: Namen | D15: Beeldende kunst | E15: =If(IFERROR(SEARCH(E$1, $D15),0) >= 1, true,false) -> FALSE | F15: =If(IFERROR(SEARCH(F$1, $D15),0) >= 1, true,false) -> FALSE | G15: =If(IFERROR(SEARCH(G$1, $D15),0) >= 1, true,false) -> FALSE | H15: =If(IFERROR(SEARCH(H$1, $D15),0) >= 1, true,false) -> FALSE | I15: =If(IFERROR(SEARCH(I$1, $D15),0) >= 1, true,false) -> FALSE | J15: =If(IFERROR(SEARCH(J$1, $D15),0) >= 1, true,false) -> TRUE | K15: =If(IFERROR(SEARCH(K$1, $D15),0) >= 1, true,false) -> FALSE | M15: TRUE | N15: FALSE | O15: FALSE | P15: FALSE | Q15: =IF(ISBLANK(A15),B15,A15) -> Félicien Rops Museum | R15: 0 | S15: FALSE | T15: TRUE | U15: 8
A16: Museum voor Oude Kunsten | B16: TreM.a | Musée des Arts anciens | C16: Namen | D16: Beeldende kunst | E16: =If(IFERROR(SEARCH(E$1, $D16),0) >= 1, true,false) -> FALSE | F16: =If(IFERROR(SEARCH(F$1, $D16),0) >= 1, true,false) -> FALSE | G16: =If(IFERROR(SEARCH(G$1, $D16),0) >= 1, true,false) -> FALSE | H16: =If(IFERROR(SEARCH(H$1, $D16),0) >= 1, true,false) -> FALSE | I16: =If(IFERROR(SEARCH(I$1, $D16),0) >= 1, true,false) -> FALSE | J16: =If(IFERROR(SEARCH(J$1, $D16),0) >= 1, true,false) -> TRUE | K16: =If(IFERROR(SEARCH(K$1, $D16),0) >= 1, true,false) -> FALSE | M16: TRUE | N16: FALSE | O16: FALSE | P16: FALSE | Q16: =IF(ISBLANK(A16),B16,A16) -> Museum voor Oude Kunsten | R16: 5 | S16: FALSE | T16: TRUE | U16: 8
A17: Abdijmuseum Ten Duinen | B17: Musée de l’Abbaye des Dunes | C17: West-Vlaanderen | D17: Geschiedenis en archeologie, Wetenschap en technologie, Architectuur | E17: =If(IFERROR(SEARCH(E$1, $D17),0) >= 1, true,false) -> TRUE | F17: =If(IFERROR(SEARCH(F$1, $D17),0) >= 1, true,false) -> TRUE | G17: =If(IFERROR(SEARCH(G$1, $D17),0) >= 1, true,false) -> FALSE | H17: =If(IFERROR(SEARCH(H$1, $D17),0) >= 1, true,false) -> FALSE | I17: =If(IFERROR(SEARCH(I$1, $D17),0) >= 1, true,false) -> TRUE | J17: =If(IFERROR(SEARCH(J$1, $D17),0) >= 1, true,false) -> FALSE | K17: =If(IFERROR(SEARCH(K$1, $D17),0) >= 1, true,false) -> FALSE | M17: TRUE | N17: FALSE | O17: TRUE | P17: FALSE | Q17: =IF(ISBLANK(A17),B17,A17) -> Abdijmuseum Ten Duinen | R17: 10 | S17: FALSE | T17: TRUE | U17: 10
A18: Adornesdomein | B18: Le domaine Adornes | C18: West-Vlaanderen | D18: Beeldende kunst, Toegepaste kunst en design, Geschiedenis en archeologie, Architectuur | E18: =If(IFERROR(SEARCH(E$1, $D18),0) >= 1, true,false) -> TRUE | F18: =If(IFERROR(SEARCH(F$1, $D18),0) >= 1, true,false) -> FALSE | G18: =If(IFERROR(SEARCH(G$1, $D18),0) >= 1, true,false) -> FALSE | H18: =If(IFERROR(SEARCH(H$1, $D18),0) >= 1, true,false) -> FALSE | I18: =If(IFERROR(SEARCH(I$1, $D18),0) >= 1, true,false) -> TRUE | J18: =If(IFERROR(SEARCH(J$1, $D18),0) >= 1, true,false) -> TRUE | K18: =If(IFERROR(SEARCH(K$1, $D18),0) >= 1, true,false) -> TRUE | M18: TRUE | N18: TRUE | O18: FALSE | P18: FALSE | Q18: =IF(ISBLANK(A18),B18,A18) -> Adornesdomein | R18: 10 | S18: FALSE | T18: FALSE
A19: Atlantikwall Raversyde | C19: West-Vlaanderen | D19: Beeldende kunst, Toegepaste kunst en design, Geschiedenis en archeologie, Wetenschap en technologie, Architectuur | E19: =If(IFERROR(SEARCH(E$1, $D19),0) >= 1, true,false) -> TRUE | F19: =If(IFERROR(SEARCH(F$1, $D19),0) >= 1, true,false) -> TRUE | G19: =If(IFERROR(SEARCH(G$1, $D19),0) >= 1, true,false) -> FALSE | H19: =If(IFERROR(SEARCH(H$1, $D19),0) >= 1, true,false) -> FALSE | I19: =If(IFERROR(SEARCH(I$1, $D19),0) >= 1, true,false) -> TRUE | J19: =If(IFERROR(SEARCH(J$1, $D19),0) >= 1, true,false) -> TRUE | K19: =If(IFERROR(SEARCH(K$1, $D19),0) >= 1, true,false) -> TRUE | M19: TRUE | N19: TRUE | O19: TRUE | P19: TRUE | Q19: =IF(ISBLANK(A19),B19,A19) -> Atlantikwall Raversyde | R19: 10 | S19: FALSE | T19: TRUE | U19: 10
A20: Bakkerijmuseum | B20: Musée de la Boulangerie | C20: West-Vlaanderen | D20: Geschiedenis en archeologie | E20: =If(IFERROR(SEARCH(E$1, $D20),0) >= 1, true,false) -> TRUE | F20: =If(IFERROR(SEARCH(F$1, $D20),0) >= 1, true,false) -> FALSE | G20: =If(IFERROR(SEARCH(G$1, $D20),0) >= 1, true,false) -> FALSE | H20: =If(IFERROR(SEARCH(H$1, $D20),0) >= 1, true,false) -> FALSE | I20: =If(IFERROR(SEARCH(I$1, $D20),0) >= 1, true,false) -> FALSE | J20: =If(IFERROR(SEARCH(J$1, $D20),0) >= 1, true,false) -> FALSE | K20: =If(IFERROR(SEARCH(K$1, $D20),0) >= 1, true,false) -> FALSE | M20: TRUE | N20: TRUE | O20: TRUE | P20: TRUE | Q20: =IF(ISBLANK(A20),B20,A20) -> Bakkerijmuseum | R20: 8 | S20: FALSE | T20: FALSE
A21: Belfort van Brugge | B21: Beffroi de Bruges | C21: West-Vlaanderen | D21: Geschiedenis en archeologie, Wetenschap en technologie, Architectuur | E21: =If(IFERROR(SEARCH(E$1, $D21),0) >= 1, true,false) -> TRUE | F21: =If(IFERROR(SEARCH(F$1, $D21),0) >= 1, true,false) -> TRUE | G21: =If(IFERROR(SEARCH(G$1, $D21),0) >= 1, true,false) -> FALSE | H21: =If(IFERROR(SEARCH(H$1, $D21),0) >= 1, true,false) -> FALSE | I21: =If(IFERROR(SEARCH(I$1, $D21),0) >= 1, true,false) -> TRUE | J21: =If(IFERROR(SEARCH(J$1, $D21),0) >= 1, true,false) -> FALSE | K21: =If(IFERROR(SEARCH(K$1, $D21),0) >= 1, true,false) -> FALSE | M21: FALSE | N21: FALSE | O21: FALSE | P21: FALSE | Q21: =IF(ISBLANK(A21),B21,A21) -> Belfort van Brugge | R21: 15 | S21: FALSE | T21: FALSE
A22: Belle Epoque Centrum | B22: Centre Belle Epoque | C22: West-Vlaanderen | D22: Geschiedenis en archeologie | E22: =If(IFERROR(SEARCH(E$1, $D22),0) >= 1, true,false) -> TRUE | F22: =If(IFERROR(SEARCH(F$1, $D22),0) >= 1, true,false) -> FALSE | G22: =If(IFERROR(SEARCH(G$1, $D22),0) >= 1, true,false) -> FALSE | H22: =If(IFERROR(SEARCH(H$1, $D22),0) >= 1, true,false) -> FALSE | I22: =If(IFERROR(SEARCH(I$1, $D22),0) >= 1, true,false) -> FALSE | J22: =If(IFERROR(SEARCH(J$1, $D22),0) >= 1, true,false) -> FALSE | K22: =If(IFERROR(SEARCH(K$1, $D22),0) >= 1, true,false) -> FALSE | M22: TRUE | N22: FALSE | O22: FALSE | P22: FALSE | Q22: =IF(ISBLANK(A22),B22,A22) -> Belle Epoque Centrum | R22: 5 | S22: FALSE | T22: FALSE
A23: Brugse Vrije | B23: Franc de Bruges | C23: West-Vlaanderen | D23: Beeldende kunst, Toegepaste kunst en design, Geschiedenis en archeologie | E23: =If(IFERROR(SEARCH(E$1, $D23),0) >= 1, true,false) -> TRUE | F23: =If(IFERROR(SEARCH(F$1, $D23),0) >= 1, true,false) -> FALSE | G23: =If(IFERROR(SEARCH(G$1, $D23),0) >= 1, true,false) -> FALSE | H23: =If(IFERROR(SEARCH(H$1, $D23),0) >= 1, true,false) -> FALSE | I23: =If(IFERROR(SEARCH(I$1, $D23),0) >= 1, true,false) -> FALSE | J23: =If(IFERROR(SEARCH(J$1, $D23),0) >= 1, true,false) -> TRUE | K23: =If(IFERROR(SEARCH(K$1, $D23),0) >= 1, true,false) -> TRUE | M23: FALSE | N23: FALSE | O23: FALSE | P23: FALSE | Q23: =IF(ISBLANK(A23),B23,A23) -> Brugse Vrije | R23: 3 | S23: FALSE | T23: FALSE
A24: Dodengang | B24: Boyau de la Mort | C24: West-Vlaanderen | D24: Geschiedenis en archeologie | E24: =If(IFERROR(SEARCH(E$1, $D24),0) >= 1, true,false) -> TRUE | F24: =If(IFERROR(SEARCH(F$1, $D24),0) >= 1, true,false) -> FALSE | G24: =If(IFERROR(SEARCH(G$1, $D24),0) >= 1, true,false) -> FALSE | H24: =If(IFERROR(SEARCH(H$1, $D24),0) >= 1, true,false) -> FALSE | I24: =If(IFERROR(SEARCH(I$1, $D24),0) >= 1, true,false) -> FALSE | J24: =If(IFERROR(SEARCH(J$1, $D24),0) >= 1, true,false) -> FALSE | K24: =If(IFERROR(SEARCH(K$1, $D24),0) >= 1, true,false) -> FALSE | M24: FALSE | N24: FALSE | O24: TRUE | P24: FALSE | Q24: =IF(ISBLANK(A24),B24,A24) -> Dodengang | R24: 6 | S24: FALSE | T24: FALSE
B25: Eperon d’Or | C25: West-Vlaanderen | D25: Geschiedenis en archeologie, Wetenschap en technologie, Architectuur, Mode | E25: =If(IFERROR(SEARCH(E$1, $D25),0) >= 1, true,false) -> TRUE | F25: =If(IFERROR(SEARCH(F$1, $D25),0) >= 1, true,false) -> TRUE | G25: =If(IFERROR(SEARCH(G$1, $D25),0) >= 1, true,false) -> TRUE | H25: =If(IFERROR(SEARCH(H$1, $D25),0) >= 1, true,false) -> FALSE | I25: =If(IFERROR(SEARCH(I$1, $D25),0) >= 1, true,false) -> TRUE | J25: =If(IFERROR(SEARCH(J$1, $D25),0) >= 1, true,false) -> FALSE | K25: =If(IFERROR(SEARCH(K$1, $D25),0) >= 1, true,false) -> FALSE | M25: TRUE | N25: FALSE | O25: TRUE | P25: FALSE | Q25: =IF(ISBLANK(A25),B25,A25) -> Eperon d’Or | R25: 8 | S25: FALSE | T25: TRUE | U25: 8
A26: Gezellehuis | B26: Maison Gezelle | C26: West-Vlaanderen | D26: Literatuur | E26: =If(IFERROR(SEARCH(E$1, $D26),0) >= 1, true,false) -> FALSE | F26: =If(IFERROR(SEARCH(F$1, $D26),0) >= 1, true,false) -> FALSE | G26: =If(IFERROR(SEARCH(G$1, $D26),0) >= 1, true,false) -> FALSE | H26: =If(IFERROR(SEARCH(H$1, $D26),0) >= 1, true,false) -> TRUE | I26: =If(IFERROR(SEARCH(I$1, $D26),0) >= 1, true,false) -> FALSE | J26: =If(IFERROR(SEARCH(J$1, $D26),0) >= 1, true,false) -> FALSE | K26: =If(IFERROR(SEARCH(K$1, $D26),0) >= 1, true,false) -> FALSE | M26: FALSE | N26: FALSE | O26: FALSE | P26: FALSE | Q26: =IF(ISBLANK(A26),B26,A26) -> Gezellehuis | R26: 0 | S26: FALSE | T26: FALSE
A27: Groeningemuseum | B27: Musée Groeninge | C27: West-Vlaanderen | D27: Beeldende kunst | E27: =If(IFERROR(SEARCH(E$1, $D27),0) >= 1, true,false) -> FALSE | F27: =If(IFERROR(SEARCH(F$1, $D27),0) >= 1, true,false) -> FALSE | G27: =If(IFERROR(SEARCH(G$1, $D27),0) >= 1, true,false) -> FALSE | H27: =If(IFERROR(SEARCH(H$1, $D27),0) >= 1, true,false) -> FALSE | I27: =If(IFERROR(SEARCH(I$1, $D27),0) >= 1, true,false) -> FALSE | J27: =If(IFERROR(SEARCH(J$1, $D27),0) >= 1, true,false) -> TRUE | K27: =If(IFERROR(SEARCH(K$1, $D27),0) >= 1, true,false) -> FALSE | M27: TRUE | N27: FALSE | O27: FALSE | P27: FALSE | Q27: =IF(ISBLANK(A27),B27,A27) -> Groeningemuseum | R27: 15 | S27: FALSE | T27: FALSE
A28: Gruuthusemuseum | B28: Musée Gruuthuse | C28: West-Vlaanderen | D28: Beeldende kunst, Toegepaste kunst en design, Geschiedenis en archeologie, Architectuur | E28: =If(IFERROR(SEARCH(E$1, $D28),0) >= 1, true,false) -> TRUE | F28: =If(IFERROR(SEARCH(F$1, $D28),0) >= 1, true,false) -> FALSE | G28: =If(IFERROR(SEARCH(G$1, $D28),0) >= 1, true,false) -> FALSE | H28: =If(IFERROR(SEARCH(H$1, $D28),0) >= 1, true,false) -> FALSE | I28: =If(IFERROR(SEARCH(I$1, $D28),0) >= 1, true,false) -> TRUE | J28: =If(IFERROR(SEARCH(J$1, $D28),0) >= 1, true,false) -> TRUE | K28: =If(IFERROR(SEARCH(K$1, $D28),0) >= 1, true,false) -> TRUE | M28: FALSE | N28: FALSE | O28: FALSE | P28: FALSE | Q28: =IF(ISBLANK(A28),B28,A28) -> Gruuthusemuseum | R28: 15 | S28: FALSE | T28: FALSE
A29: Het James Ensorhuis | B29: La Maison de James Ensor | C29: West-Vlaanderen | D29: Beeldende kunst | E29: =If(IFERROR(SEARCH(E$1, $D29),0) >= 1, true,false) -> FALSE | F29: =If(IFERROR(SEARCH(F$1, $D29),0) >= 1, true,false) -> FALSE | G29: =If(IFERROR(SEARCH(G$1, $D29),0) >= 1, true,false) -> FALSE | H29: =If(IFERROR(SEARCH(H$1, $D29),0) >= 1, true,false) -> FALSE | I29: =If(IFERROR(SEARCH(I$1, $D29),0) >= 1, true,false) -> FALSE | J29: =If(IFERROR(SEARCH(J$1, $D29),0) >= 1, true,false) -> TRUE | K29: =If(IFERROR(SEARCH(K$1, $D29),0) >= 1, true,false) -> FALSE | M29: TRUE | N29: FALSE | O29: FALSE | P29: FALSE | Q29: =IF(ISBLANK(A29),B29,A29) -> Het James Ensorhuis | R29: 13 | S29: FALSE | T29: TRUE | U29: 13
A30: Het Lijsternest | Streuvelshuis & Schrijversresidentie | C30: West-Vlaanderen | D30: Beeldende kunst, Architectuur, Literatuur | E30: =If(IFERROR(SEARCH(E$1, $D30),0) >= 1, true,false) -> FALSE | F30: =If(IFERROR(SEARCH(F$1, $D30),0) >= 1, true,false) -> FALSE | G30: =If(IFERROR(SEARCH(G$1, $D30),0) >= 1, true,false) -> FALSE | H30: =If(IFERROR(SEARCH(H$1, $D30),0) >= 1, true,false) -> TRUE | I30: =If(IFERROR(SEARCH(I$1, $D30),0) >= 1, true,false) -> TRUE | J30: =If(IFERROR(SEARCH(J$1, $D30),0) >= 1, true,false) -> TRUE | K30: =If(IFERROR(SEARCH(K$1, $D30),0) >= 1, true,false) -> FALSE | M30: TRUE | N30: FALSE | O30: TRUE | P30: FALSE | Q30: =IF(ISBLANK(A30),B30,A30) -> Het Lijsternest | Streuvelshuis & Schrijversresidentie | R30: 3 | S30: TRUE | T30: FALSE
A31: HEY Museum | C31: West-Vlaanderen | D31: Beeldende kunst, Geschiedenis en archeologie | E31: =If(IFERROR(SEARCH(E$1, $D31),0) >= 1, true,false) -> TRUE | F31: =If(IFERROR(SEARCH(F$1, $D31),0) >= 1, true,false) -> FALSE | G31: =If(IFERROR(SEARCH(G$1, $D31),0) >= 1, true,false) -> FALSE | H31: =If(IFERROR(SEARCH(H$1, $D31),0) >= 1, true,false) -> FALSE | I31: =If(IFERROR(SEARCH(I$1, $D31),0) >= 1, true,false) -> FALSE | J31: =If(IFERROR(SEARCH(J$1, $D31),0) >= 1, true,false) -> TRUE | K31: =If(IFERROR(SEARCH(K$1, $D31),0) >= 1, true,false) -> FALSE | M31: TRUE | N31: FALSE | O31: FALSE | P31: FALSE | Q31: =IF(ISBLANK(A31),B31,A31) -> HEY Museum | R31: 10 | S31: FALSE | T31: FALSE
A32: Hopmuseum Poperinge | B32: Musée du Houblon Poperinge | C32: West-Vlaanderen | D32: Geschiedenis en archeologie | E32: =If(IFERROR(SEARCH(E$1, $D32),0) >= 1, true,false) -> TRUE | F32: =If(IFERROR(SEARCH(F$1, $D32),0) >= 1, true,false) -> FALSE | G32: =If(IFERROR(SEARCH(G$1, $D32),0) >= 1, true,false) -> FALSE | H32: =If(IFERROR(SEARCH(H$1, $D32),0) >= 1, true,false) -> FALSE | I32: =If(IFERROR(SEARCH(I$1, $D32),0) >= 1, true,false) -> FALSE | J32: =If(IFERROR(SEARCH(J$1, $D32),0) >= 1, true,false) -> FALSE | K32: =If(IFERROR(SEARCH(K$1, $D32),0) >= 1, true,false) -> FALSE | M32: TRUE | N32: TRUE | O32: FALSE | P32: FALSE | Q32: =IF(ISBLANK(A32),B32,A32) -> Hopmuseum Poperinge | R32: 7 | S32: FALSE | T32: FALSE
A33: In Flanders Fields Museum | B33: Musée In Flanders Fields | C33: West-Vlaanderen | D33: Geschiedenis en archeologie | E33: =If(IFERROR(SEARCH(E$1, $D33),0) >= 1, true,false) -> TRUE | F33: =If(IFERROR(SEARCH(F$1, $D33),0) >= 1, true,false) -> FALSE | G33: =If(IFERROR(SEARCH(G$1, $D33),0) >= 1, true,false) -> FALSE | H33: =If(IFERROR(SEARCH(H$1, $D33),0) >= 1, true,false) -> FALSE | I33: =If(IFERROR(SEARCH(I$1, $D33),0) >= 1, true,false) -> FALSE | J33: =If(IFERROR(SEARCH(J$1, $D33),0) >= 1, true,false) -> FALSE | K33: =If(IFERROR(SEARCH(K$1, $D33),0) >= 1, true,false) -> FALSE | M33: TRUE | N33: TRUE | O33: FALSE | P33: FALSE | Q33: =IF(ISBLANK(A33),B33,A33) -> In Flanders Fields Museum | R33: 12 | S33: FALSE | T33: TRUE | U33: 12
A34: Kantmuseum Brugge | B34: Musée de la Dentelle Bruges | C34: West-Vlaanderen | D34: Toegepaste kunst en design, Geschiedenis en archeologie, Mode | E34: =If(IFERROR(SEARCH(E$1, $D34),0) >= 1, true,false) -> TRUE | F34: =If(IFERROR(SEARCH(F$1, $D34),0) >= 1, true,false) -> FALSE | G34: =If(IFERROR(SEARCH(G$1, $D34),0) >= 1, true,false) -> TRUE | H34: =If(IFERROR(SEARCH(H$1, $D34),0) >= 1, true,false) -> FALSE | I34: =If(IFERROR(SEARCH(I$1, $D34),0) >= 1, true,false) -> FALSE | J34: =If(IFERROR(SEARCH(J$1, $D34),0) >= 1, true,false) -> FALSE | K34: =If(IFERROR(SEARCH(K$1, $D34),0) >= 1, true,false) -> TRUE | M34: TRUE | N34: FALSE | O34: FALSE | P34: FALSE | Q34: =IF(ISBLANK(A34),B34,A34) -> Kantmuseum Brugge | R34: 8 | S34: FALSE | T34: FALSE
A35: Kasteel van Loppem | B35: Château de Loppem | C35: West-Vlaanderen | D35: Beeldende kunst, Geschiedenis en archeologie | E35: =If(IFERROR(SEARCH(E$1, $D35),0) >= 1, true,false) -> TRUE | F35: =If(IFERROR(SEARCH(F$1, $D35),0) >= 1, true,false) -> FALSE | G35: =If(IFERROR(SEARCH(G$1, $D35),0) >= 1, true,false) -> FALSE | H35: =If(IFERROR(SEARCH(H$1, $D35),0) >= 1, true,false) -> FALSE | I35: =If(IFERROR(SEARCH(I$1, $D35),0) >= 1, true,false) -> FALSE | J35: =If(IFERROR(SEARCH(J$1, $D35),0) >= 1, true,false) -> TRUE | K35: =If(IFERROR(SEARCH(K$1, $D35),0) >= 1, true,false) -> FALSE | M35: TRUE | N35: FALSE | O35: TRUE | P35: FALSE | Q35: =IF(ISBLANK(A35),B35,A35) -> Kasteel van Loppem | R35: 9 | S35: FALSE | T35: FALSE
A36: KOERS | Museum van de Wielersport | B36: Musée de la Course Cycliste | C36: West-Vlaanderen | D36: Geschiedenis en archeologie, Wetenschap en technologie | E36: =If(IFERROR(SEARCH(E$1, $D36),0) >= 1, true,false) -> TRUE | F36: =If(IFERROR(SEARCH(F$1, $D36),0) >= 1, true,false) -> TRUE | G36: =If(IFERROR(SEARCH(G$1, $D36),0) >= 1, true,false) -> FALSE | H36: =If(IFERROR(SEARCH(H$1, $D36),0) >= 1, true,false) -> FALSE | I36: =If(IFERROR(SEARCH(I$1, $D36),0) >= 1, true,false) -> FALSE | J36: =If(IFERROR(SEARCH(J$1, $D36),0) >= 1, true,false) -> FALSE | K36: =If(IFERROR(SEARCH(K$1, $D36),0) >= 1, true,false) -> FALSE | M36: TRUE | N36: TRUE | O36: FALSE | P36: TRUE | Q36: =IF(ISBLANK(A36),B36,A36) -> KOERS | Museum van de Wielersport | R36: 9 | S36: FALSE | T36: FALSE
A37: Museum aan de IJzer | B37: Musée la tour de L’Yser | C37: West-Vlaanderen | D37: Geschiedenis en archeologie | E37: =If(IFERROR(SEARCH(E$1, $D37),0) >= 1, true,false) -> TRUE | F37: =If(IFERROR(SEARCH(F$1, $D37),0) >= 1, true,false) -> FALSE | G37: =If(IFERROR(SEARCH(G$1, $D37),0) >= 1, true,false) -> FALSE | H37: =If(IFERROR(SEARCH(H$1, $D37),0) >= 1, true,false) -> FALSE | I37: =If(IFERROR(SEARCH(I$1, $D37),0) >= 1, true,false) -> FALSE | J37: =If(IFERROR(SEARCH(J$1, $D37),0) >= 1, true,false) -> FALSE | K37: =If(IFERROR(SEARCH(K$1, $D37),0) >= 1, true,false) -> FALSE | M37: TRUE | N37: TRUE | O37: TRUE | P37: FALSE | Q37: =IF(ISBLANK(A37),B37,A37) -> Museum aan de IJzer | R37: 9.5 | S37: FALSE | T37: TRUE | U37: 9.5
A38: Museum Sint-Janshospitaal | B38: Musée Hôpital Saint-Jean | C38: West-Vlaanderen | D38: Beeldende kunst, Toegepaste kunst en design, Geschiedenis en archeologie, Wetenschap en technologie, Architectuur | E38: =If(IFERROR(SEARCH(E$1, $D38),0) >= 1, true,false) -> TRUE | F38: =If(IFERROR(SEARCH(F$1, $D38),0) >= 1, true,false) -> TRUE | G38: =If(IFERROR(SEARCH(G$1, $D38),0) >= 1, true,false) -> FALSE | H38: =If(IFERROR(SEARCH(H$1, $D38),0) >= 1, true,false) -> FALSE | I38: =If(IFERROR(SEARCH(I$1, $D38),0) >= 1, true,false) -> TRUE | J38: =If(IFERROR(SEARCH(J$1, $D38),0) >= 1, true,false) -> TRUE | K38: =If(IFERROR(SEARCH(K$1, $D38),0) >= 1, true,false) -> TRUE | M38: TRUE | N38: FALSE | O38: FALSE | P38: FALSE | Q38: =IF(ISBLANK(A38),B38,A38) -> Museum Sint-Janshospitaal | R38: 15 | S38: FALSE | T38: TRUE | U38: 15
A39: Mu.ZEE | Kunstmuseum aan Zee | B39: Musée Art-sur-Mer | C39: West-Vlaanderen | D39: Beeldende kunst | E39: =If(IFERROR(SEARCH(E$1, $D39),0) >= 1, true,false) -> FALSE | F39: =If(IFERROR(SEARCH(F$1, $D39),0) >= 1, true,false) -> FALSE | G39: =If(IFERROR(SEARCH(G$1, $D39),0) >= 1, true,false) -> FALSE | H39: =If(IFERROR(SEARCH(H$1, $D39),0) >= 1, true,false) -> FALSE | I39: =If(IFERROR(SEARCH(I$1, $D39),0) >= 1, true,false) -> FALSE | J39: =If(IFERROR(SEARCH(J$1, $D39),0) >= 1, true,false) -> TRUE | K39: =If(IFERROR(SEARCH(K$1, $D39),0) >= 1, true,false) -> FALSE | M39: TRUE | N39: FALSE | O39: FALSE | P39: FALSE | Q39: =IF(ISBLANK(A39),B39,A39) -> Mu.ZEE | Kunstmuseum aan Zee | R39: 12 | S39: TRUE | T39: TRUE | U39: 12
A40: Nationaal Tabaksmuseum | B40: Musée National du Tabac | C40: West-Vlaanderen | D40: Geschiedenis en archeologie | E40: =If(IFERROR(SEARCH(E$1, $D40),0) >= 1, true,false) -> TRUE | F40: =If(IFERROR(SEARCH(F$1, $D40),0) >= 1, true,false) -> FALSE | G40: =If(IFERROR(SEARCH(G$1, $D40),0) >= 1, true,false) -> FALSE | H40: =If(IFERROR(SEARCH(H$1, $D40),0) >= 1, true,false) -> FALSE | I40: =If(IFERROR(SEARCH(I$1, $D40),0) >= 1, true,false) -> FALSE | J40: =If(IFERROR(SEARCH(J$1, $D40),0) >= 1, true,false) -> FALSE | K40: =If(IFERROR(SEARCH(K$1, $D40),0) >= 1, true,false) -> FALSE | M40: FALSE | N40: FALSE | O40: FALSE | P40: FALSE | Q40: =IF(ISBLANK(A40),B40,A40) -> Nationaal Tabaksmuseum | R40: 4.5 | S40: FALSE | T40: TRUE | U40: 4.5
...

Sheet Blad14
A1: Musea - Nederlandse benaming (Title) | B1: Musea - Franse benaming (Alternative Title) | C1: Provincie | D1: Alle Thema's | E1: Geschiedenis en archeologie | F1: Wetenschap en technologie | G1: Mode | H1: Literatuur | I1: Architectuur | J1: Beeldende kunst | K1: Toegepaste kunst en design | M1: Shop | N1: Café | O1: Parking | P1: Restaurant | Q1: Algemene naam --> als geen NL naam dan FR | R1: Prijs | S1: Tijdelijk gesloten | T1: Tijdelijke tentoonstelling(en) | U1: Prijs incl. tijdelijke tentoonstelling | X1: # Museums | Y1: Average Price | Z1: Median
A2: Archeologisch museum van de Boven-Maas | B2: Musée archéologique de la Haute-Meuse | C2: Namen | D2: Geschiedenis en archeologie | E2: =IF(IFERROR(SEARCH(E$1, $D2),0) >= 1, TRUE,FALSE) -> TRUE | F2: =IF(IFERROR(SEARCH(F$1, $D2),0) >= 1, TRUE,FALSE) -> FALSE | G2: =IF(IFERROR(SEARCH(G$1, $D2),0) >= 1, TRUE,FALSE) -> FALSE | H2: =IF(IFERROR(SEARCH(H$1, $D2),0) >= 1, TRUE,FALSE) -> FALSE | I2: =IF(IFERROR(SEARCH(I$1, $D2),0) >= 1, TRUE,FALSE) -> FALSE | J2: =IF(IFERROR(SEARCH(J$1, $D2),0) >= 1, TRUE,FALSE) -> FALSE | K2: =IF(IFERROR(SEARCH(K$1, $D2),0) >= 1, TRUE,FALSE) -> FALSE | M2: TRUE | N2: FALSE | O2: TRUE | P2: FALSE | Q2: =IF(ISBLANK(A2),B2,A2) -> Archeologisch museum van de Boven-Maas | R2: 3.5 | S2: FALSE | T2: FALSE | W2: Namen | X2: =COUNTIF(C:C, "Namen") -> 15 | Y2: =AVERAGEIF(C:C, "Namen",R:R) -> 5.9666667 | Z2: =MEDIAN(R2:R16) -> 6
A3: Citadel van Namen / Bezoekerscentrum Terra Nova en toeristentreintje | B3: =IFERROR(__xludf.DUMMYFUNCTION("SPLIT(A3, "" - "", FALSE,FALSE)"),"Citadel van Namen / Bezoekerscentrum Terra Nova en toeristentreintje") -> Citadel van Namen / Bezoekerscentrum Terra Nova en toeristentreintje | C3: Namen | D3: Geschiedenis en archeologie | E3: =IF(IFERROR(SEARCH(E$1, $D3),0) >= 1, TRUE,FALSE) -> TRUE | F3: =IF(IFERROR(SEARCH(F$1, $D3),0) >= 1, TRUE,FALSE) -> FALSE | G3: =IF(IFERROR(SEARCH(G$1, $D3),0) >= 1, TRUE,FALSE) -> FALSE | H3: =IF(IFERROR(SEARCH(H$1, $D3),0) >= 1, TRUE,FALSE) -> FALSE | I3: =IF(IFERROR(SEARCH(I$1, $D3),0) >= 1, TRUE,FALSE) -> FALSE | J3: =IF(IFERROR(SEARCH(J$1, $D3),0) >= 1, TRUE,FALSE) -> FALSE | K3: =IF(IFERROR(SEARCH(K$1, $D3),0) >= 1, TRUE,FALSE) -> FALSE | M3: TRUE | N3: TRUE | O3: FALSE | P3: FALSE | Q3: =IF(ISBLANK(A3),B3,A3) -> Citadel van Namen / Bezoekerscentrum Terra Nova en toeristentreintje | R3: 6 | S3: FALSE | T3: FALSE | W3: West-Vlaanderen | X3: =COUNTIF(C:C, "West-Vlaanderen") -> 41 | Y3: =AVERAGEIF(C:C, "West-Vlaanderen",R:R) -> 9.1463415 | Z3: =MEDIAN(R17:R57) -> 9
A4: NAM-IP Computermuseum | B4: Computer Museum NAM-IP | C4: Namen | D4: Wetenschap en technologie | E4: =IF(IFERROR(SEARCH(E$1, $D4),0) >= 1, TRUE,FALSE) -> FALSE | F4: =IF(IFERROR(SEARCH(F$1, $D4),0) >= 1, TRUE,FALSE) -> TRUE | G4: =IF(IFERROR(SEARCH(G$1, $D4),0) >= 1, TRUE,FALSE) -> FALSE | H4: =IF(IFERROR(SEARCH(H$1, $D4),0) >= 1, TRUE,FALSE) -> FALSE | I4: =IF(IFERROR(SEARCH(I$1, $D4),0) >= 1, TRUE,FALSE) -> FALSE | J4: =IF(IFERROR(SEARCH(J$1, $D4),0) >= 1, TRUE,FALSE) -> FALSE | K4: =IF(IFERROR(SEARCH(K$1, $D4),0) >= 1, TRUE,FALSE) -> FALSE | M4: TRUE | N4: TRUE | O4: TRUE | P4: FALSE | Q4: =IF(ISBLANK(A4),B4,A4) -> NAM-IP Computermuseum | R4: 8 | S4: FALSE | T4: FALSE | W4: Antwerpen | X4: 35 | Y4: =AVERAGE($R$58:$R$91) -> 9.25 | Z4: =MEDIAN($R$58:$R$91) -> 10
A5: Ecomuseum van de Viroin | B5: Écomusée du Viroin | C5: Namen | D5: Geschiedenis en archeologie | E5: =IF(IFERROR(SEARCH(E$1, $D5),0) >= 1, TRUE,FALSE) -> TRUE | F5: =IF(IFERROR(SEARCH(F$1, $D5),0) >= 1, TRUE,FALSE) -> FALSE | G5: =IF(IFERROR(SEARCH(G$1, $D5),0) >= 1, TRUE,FALSE) -> FALSE | H5: =IF(IFERROR(SEARCH(H$1, $D5),0) >= 1, TRUE,FALSE) -> FALSE | I5: =IF(IFERROR(SEARCH(I$1, $D5),0) >= 1, TRUE,FALSE) -> FALSE | J5: =IF(IFERROR(SEARCH(J$1, $D5),0) >= 1, TRUE,FALSE) -> FALSE | K5: =IF(IFERROR(SEARCH(K$1, $D5),0) >= 1, TRUE,FALSE) -> FALSE | M5: TRUE | N5: FALSE | O5: FALSE | P5: FALSE | Q5: =IF(ISBLANK(A5),B5,A5) -> Ecomuseum van de Viroin | R5: 4 | S5: FALSE | T5: TRUE | U5: 4 | W5: Waals-Brabant | X5: 5 | Y5: =AVERAGE($R$93:$R$97) -> 8.8 | Z5: =MEDIAN($R$93:$R$97) -> 10
A6: Andenne Museum | B6: Espace Muséal d’Andenne | C6: Namen | D6: Toegepaste kunst en design, Geschiedenis en archeologie | E6: =IF(IFERROR(SEARCH(E$1, $D6),0) >= 1, TRUE,FALSE) -> TRUE | F6: =IF(IFERROR(SEARCH(F$1, $D6),0) >= 1, TRUE,FALSE) -> FALSE | G6: =IF(IFERROR(SEARCH(G$1, $D6),0) >= 1, TRUE,FALSE) -> FALSE | H6: =IF(IFERROR(SEARCH(H$1, $D6),0) >= 1, TRUE,FALSE) -> FALSE | I6: =IF(IFERROR(SEARCH(I$1, $D6),0) >= 1, TRUE,FALSE) -> FALSE | J6: =IF(IFERROR(SEARCH(J$1, $D6),0) >= 1, TRUE,FALSE) -> FALSE | K6: =IF(IFERROR(SEARCH(K$1, $D6),0) >= 1, TRUE,FALSE) -> TRUE | M6: TRUE | N6: FALSE | O6: FALSE | P6: FALSE | Q6: =IF(ISBLANK(A6),B6,A6) -> Andenne Museum | R6: 10 | S6: FALSE | T6: FALSE | W6: Vlaams-Brabant | X6: 13 | Y6: =AVERAGE($R$98:$R$110) -> 8.1923077 | Z6: =MEDIAN($R$98:$R$110) -> 10
B7: Le Delta | C7: Namen | D7: Beeldende kunst | E7: =IF(IFERROR(SEARCH(E$1, $D7),0) >= 1, TRUE,FALSE) -> FALSE | F7: =IF(IFERROR(SEARCH(F$1, $D7),0) >= 1, TRUE,FALSE) -> FALSE | G7: =IF(IFERROR(SEARCH(G$1, $D7),0) >= 1, TRUE,FALSE) -> FALSE | H7: =IF(IFERROR(SEARCH(H$1, $D7),0) >= 1, TRUE,FALSE) -> FALSE | I7: =IF(IFERROR(SEARCH(I$1, $D7),0) >= 1, TRUE,FALSE) -> FALSE | J7: =IF(IFERROR(SEARCH(J$1, $D7),0) >= 1, TRUE,FALSE) -> TRUE | K7: =IF(IFERROR(SEARCH(K$1, $D7),0) >= 1, TRUE,FALSE) -> FALSE | M7: TRUE | N7: FALSE | O7: FALSE | P7: TRUE | Q7: =IF(ISBLANK(A7),B7,A7) -> Le Delta | R7: 5 | S7: FALSE | T7: TRUE | U7: 5 | W7: Limburg | X7: =COUNTIF(C:C, "Limburg") -> 15 | Y7: =AVERAGEIF(C:C, "Limburg",R:R) -> 8.3333333 | Z7: =MEDIAN(R111,R125) -> 9
B8: Le Pavillon | C8: Namen | D8: Beeldende kunst, Wetenschap en technologie | E8: =IF(IFERROR(SEARCH(E$1, $D8),0) >= 1, TRUE,FALSE) -> FALSE | F8: =IF(IFERROR(SEARCH(F$1, $D8),0) >= 1, TRUE,FALSE) -> TRUE | G8: =IF(IFERROR(SEARCH(G$1, $D8),0) >= 1, TRUE,FALSE) -> FALSE | H8: =IF(IFERROR(SEARCH(H$1, $D8),0) >= 1, TRUE,FALSE) -> FALSE | I8: =IF(IFERROR(SEARCH(I$1, $D8),0) >= 1, TRUE,FALSE) -> FALSE | J8: =IF(IFERROR(SEARCH(J$1, $D8),0) >= 1, TRUE,FALSE) -> TRUE | K8: =IF(IFERROR(SEARCH(K$1, $D8),0) >= 1, TRUE,FALSE) -> FALSE | M8: TRUE | N8: FALSE | O8: FALSE | P8: FALSE | Q8: =IF(ISBLANK(A8),B8,A8) -> Le Pavillon | R8: 10 | S8: FALSE | T8: TRUE | U8: 10 | W8: Luik | X8: =COUNTIF(C:C, "Luik") -> 19 | Y8: =AVERAGEIF(C:C, "Luik",R:R) -> 6.6315789 | Z8: =MEDIAN(R126,R144) -> 10.5
B9: Maison du patrimoine médiéval mosan | C9: Namen | D9: Geschiedenis en archeologie | E9: =IF(IFERROR(SEARCH(E$1, $D9),0) >= 1, TRUE,FALSE) -> TRUE | F9: =IF(IFERROR(SEARCH(F$1, $D9),0) >= 1, TRUE,FALSE) -> FALSE | G9: =IF(IFERROR(SEARCH(G$1, $D9),0) >= 1, TRUE,FALSE) -> FALSE | H9: =IF(IFERROR(SEARCH(H$1, $D9),0) >= 1, TRUE,FALSE) -> FALSE | I9: =IF(IFERROR(SEARCH(I$1, $D9),0) >= 1, TRUE,FALSE) -> FALSE | J9: =IF(IFERROR(SEARCH(J$1, $D9),0) >= 1, TRUE,FALSE) -> FALSE | K9: =IF(IFERROR(SEARCH(K$1, $D9),0) >= 1, TRUE,FALSE) -> FALSE | M9: TRUE | N9: FALSE | O9: TRUE | P9: FALSE | Q9: =IF(ISBLANK(A9),B9,A9) -> Maison du patrimoine médiéval mosan | R9: 6 | S9: FALSE | T9: TRUE | U9: 6 | W9: Henegouwen | X9: =COUNTIF(C:C,"Henegouwen") -> 37 | Y9: =AVERAGEIF(C:C,"Henegouwen",R:R) -> 6.5405405 | Z9: =MEDIAN(R145:R181) -> 6
A10: Archeopark van Rochefort | B10: Malagne | Archéoparc de Rochefort | C10: Namen | D10: Geschiedenis en archeologie | E10: =IF(IFERROR(SEARCH(E$1, $D10),0) >= 1, TRUE,FALSE) -> TRUE | F10: =IF(IFERROR(SEARCH(F$1, $D10),0) >= 1, TRUE,FALSE) -> FALSE | G10: =IF(IFERROR(SEARCH(G$1, $D10),0) >= 1, TRUE,FALSE) -> FALSE | H10: =IF(IFERROR(SEARCH(H$1, $D10),0) >= 1, TRUE,FALSE) -> FALSE | I10: =IF(IFERROR(SEARCH(I$1, $D10),0) >= 1, TRUE,FALSE) -> FALSE | J10: =IF(IFERROR(SEARCH(J$1, $D10),0) >= 1, TRUE,FALSE) -> FALSE | K10: =IF(IFERROR(SEARCH(K$1, $D10),0) >= 1, TRUE,FALSE) -> FALSE | M10: TRUE | N10: TRUE | O10: TRUE | P10: FALSE | Q10: =IF(ISBLANK(A10),B10,A10) -> Archeopark van Rochefort | R10: 8 | S10: FALSE | T10: FALSE | W10: Luxemburg | X10: =COUNTIF(C:C,"Luxemburg") -> 9 | Y10: =AVERAGEIF(C:C,"Luxemburg",R:R) -> 7.0555556 | Z10: =MEDIAN(R182,R190) -> 10.5
A11: MusAfrica Namen | B11: MusAfrica Namur | C11: Namen | D11: Toegepaste kunst en design, Geschiedenis en archeologie | E11: =IF(IFERROR(SEARCH(E$1, $D11),0) >= 1, TRUE,FALSE) -> TRUE | F11: =IF(IFERROR(SEARCH(F$1, $D11),0) >= 1, TRUE,FALSE) -> FALSE | G11: =IF(IFERROR(SEARCH(G$1, $D11),0) >= 1, TRUE,FALSE) -> FALSE | H11: =IF(IFERROR(SEARCH(H$1, $D11),0) >= 1, TRUE,FALSE) -> FALSE | I11: =IF(IFERROR(SEARCH(I$1, $D11),0) >= 1, TRUE,FALSE) -> FALSE | J11: =IF(IFERROR(SEARCH(J$1, $D11),0) >= 1, TRUE,FALSE) -> FALSE | K11: =IF(IFERROR(SEARCH(K$1, $D11),0) >= 1, TRUE,FALSE) -> TRUE | M11: TRUE | N11: FALSE | O11: FALSE | P11: FALSE | Q11: =IF(ISBLANK(A11),B11,A11) -> MusAfrica Namen | R11: 8 | S11: FALSE | T11: FALSE | W11: Brussel | X11: =COUNTIF(C2:C261,"Brussel") -> 48 | Y11: =AVERAGE(R191:R238) -> 9.1875 | Z11: =MEDIAN(R191:R238) -> 10
A12: Aardbeimuseum | B12: Musée de la Fraise | C12: Namen | D12: Beeldende kunst, Geschiedenis en archeologie, Wetenschap en technologie | E12: =IF(IFERROR(SEARCH(E$1, $D12),0) >= 1, TRUE,FALSE) -> TRUE | F12: =IF(IFERROR(SEARCH(F$1, $D12),0) >= 1, TRUE,FALSE) -> TRUE | G12: =IF(IFERROR(SEARCH(G$1, $D12),0) >= 1, TRUE,FALSE) -> FALSE | H12: =IF(IFERROR(SEARCH(H$1, $D12),0) >= 1, TRUE,FALSE) -> FALSE | I12: =IF(IFERROR(SEARCH(I$1, $D12),0) >= 1, TRUE,FALSE) -> FALSE | J12: =IF(IFERROR(SEARCH(J$1, $D12),0) >= 1, TRUE,FALSE) -> TRUE | K12: =IF(IFERROR(SEARCH(K$1, $D12),0) >= 1, TRUE,FALSE) -> FALSE | M12: TRUE | N12: FALSE | O12: FALSE | P12: FALSE | Q12: =IF(ISBLANK(A12),B12,A12) -> Aardbeimuseum | R12: 6 | S12: FALSE | T12: FALSE | W12: Oost-Vlaanderen | X12: =COUNTIF(C2:C261,"Oost-Vlaanderen") -> 23 | Y12: =AVERAGE(R239:R261) -> 8.5652174 | Z12: =MEDIAN(R239:R261) -> 9
B13: Musée du Malgré-Tout | C13: Namen | D13: Geschiedenis en archeologie | E13: =IF(IFERROR(SEARCH(E$1, $D13),0) >= 1, TRUE,FALSE) -> TRUE | F13: =IF(IFERROR(SEARCH(F$1, $D13),0) >= 1, TRUE,FALSE) -> FALSE | G13: =IF(IFERROR(SEARCH(G$1, $D13),0) >= 1, TRUE,FALSE) -> FALSE | H13: =IF(IFERROR(SEARCH(H$1, $D13),0) >= 1, TRUE,FALSE) -> FALSE | I13: =IF(IFERROR(SEARCH(I$1, $D13),0) >= 1, TRUE,FALSE) -> FALSE | J13: =IF(IFERROR(SEARCH(J$1, $D13),0) >= 1, TRUE,FALSE) -> FALSE | K13: =IF(IFERROR(SEARCH(K$1, $D13),0) >= 1, TRUE,FALSE) -> FALSE | M13: TRUE | N13: FALSE | O13: FALSE | P13: FALSE | Q13: =IF(ISBLANK(A13),B13,A13) -> Musée du Malgré-Tout | R13: 5 | S13: FALSE | T13: FALSE
A14: Museum van het Klein Formaat | B14: Musée du Petit Format | C14: Namen | D14: Beeldende kunst | E14: =IF(IFERROR(SEARCH(E$1, $D14),0) >= 1, TRUE,FALSE) -> FALSE | F14: =IF(IFERROR(SEARCH(F$1, $D14),0) >= 1, TRUE,FALSE) -> FALSE | G14: =IF(IFERROR(SEARCH(G$1, $D14),0) >= 1, TRUE,FALSE) -> FALSE | H14: =IF(IFERROR(SEARCH(H$1, $D14),0) >= 1, TRUE,FALSE) -> FALSE | I14: =IF(IFERROR(SEARCH(I$1, $D14),0) >= 1, TRUE,FALSE) -> FALSE | J14: =IF(IFERROR(SEARCH(J$1, $D14),0) >= 1, TRUE,FALSE) -> TRUE | K14: =IF(IFERROR(SEARCH(K$1, $D14),0) >= 1, TRUE,FALSE) -> FALSE | M14: TRUE | N14: FALSE | O14: FALSE | P14: FALSE | Q14: =IF(ISBLANK(A14),B14,A14) -> Museum van het Klein Formaat | R14: 5 | S14: FALSE | T14: TRUE | U14: 5
A15: Félicien Rops Museum | B15: Musée Félicien Rops | C15: Namen | D15: Beeldende kunst | E15: =IF(IFERROR(SEARCH(E$1, $D15),0) >= 1, TRUE,FALSE) -> FALSE | F15: =IF(IFERROR(SEARCH(F$1, $D15),0) >= 1, TRUE,FALSE) -> FALSE | G15: =IF(IFERROR(SEARCH(G$1, $D15),0) >= 1, TRUE,FALSE) -> FALSE | H15: =IF(IFERROR(SEARCH(H$1, $D15),0) >= 1, TRUE,FALSE) -> FALSE | I15: =IF(IFERROR(SEARCH(I$1, $D15),0) >= 1, TRUE,FALSE) -> FALSE | J15: =IF(IFERROR(SEARCH(J$1, $D15),0) >= 1, TRUE,FALSE) -> TRUE | K15: =IF(IFERROR(SEARCH(K$1, $D15),0) >= 1, TRUE,FALSE) -> FALSE | M15: TRUE | N15: FALSE | O15: FALSE | P15: FALSE | Q15: =IF(ISBLANK(A15),B15,A15) -> Félicien Rops Museum | R15: 0 | S15: FALSE | T15: TRUE | U15: 8
A16: Museum voor Oude Kunsten | B16: TreM.a | Musée des Arts anciens | C16: Namen | D16: Beeldende kunst | E16: =IF(IFERROR(SEARCH(E$1, $D16),0) >= 1, TRUE,FALSE) -> FALSE | F16: =IF(IFERROR(SEARCH(F$1, $D16),0) >= 1, TRUE,FALSE) -> FALSE | G16: =IF(IFERROR(SEARCH(G$1, $D16),0) >= 1, TRUE,FALSE) -> FALSE | H16: =IF(IFERROR(SEARCH(H$1, $D16),0) >= 1, TRUE,FALSE) -> FALSE | I16: =IF(IFERROR(SEARCH(I$1, $D16),0) >= 1, TRUE,FALSE) -> FALSE | J16: =IF(IFERROR(SEARCH(J$1, $D16),0) >= 1, TRUE,FALSE) -> TRUE | K16: =IF(IFERROR(SEARCH(K$1, $D16),0) >= 1, TRUE,FALSE) -> FALSE | M16: TRUE | N16: FALSE | O16: FALSE | P16: FALSE | Q16: =IF(ISBLANK(A16),B16,A16) -> Museum voor Oude Kunsten | R16: 5 | S16: FALSE | T16: TRUE | U16: 8
A17: Abdijmuseum Ten Duinen | B17: Musée de l’Abbaye des Dunes | C17: West-Vlaanderen | D17: Geschiedenis en archeologie, Wetenschap en technologie, Architectuur | E17: =IF(IFERROR(SEARCH(E$1, $D17),0) >= 1, TRUE,FALSE) -> TRUE | F17: =IF(IFERROR(SEARCH(F$1, $D17),0) >= 1, TRUE,FALSE) -> TRUE | G17: =IF(IFERROR(SEARCH(G$1, $D17),0) >= 1, TRUE,FALSE) -> FALSE | H17: =IF(IFERROR(SEARCH(H$1, $D17),0) >= 1, TRUE,FALSE) -> FALSE | I17: =IF(IFERROR(SEARCH(I$1, $D17),0) >= 1, TRUE,FALSE) -> TRUE | J17: =IF(IFERROR(SEARCH(J$1, $D17),0) >= 1, TRUE,FALSE) -> FALSE | K17: =IF(IFERROR(SEARCH(K$1, $D17),0) >= 1, TRUE,FALSE) -> FALSE | M17: TRUE | N17: FALSE | O17: TRUE | P17: FALSE | Q17: =IF(ISBLANK(A17),B17,A17) -> Abdijmuseum Ten Duinen | R17: 10 | S17: FALSE | T17: TRUE | U17: 10
A18: Adornesdomein | B18: Le domaine Adornes | C18: West-Vlaanderen | D18: Beeldende kunst, Toegepaste kunst en design, Geschiedenis en archeologie, Architectuur | E18: =IF(IFERROR(SEARCH(E$1, $D18),0) >= 1, TRUE,FALSE) -> TRUE | F18: =IF(IFERROR(SEARCH(F$1, $D18),0) >= 1, TRUE,FALSE) -> FALSE | G18: =IF(IFERROR(SEARCH(G$1, $D18),0) >= 1, TRUE,FALSE) -> FALSE | H18: =IF(IFERROR(SEARCH(H$1, $D18),0) >= 1, TRUE,FALSE) -> FALSE | I18: =IF(IFERROR(SEARCH(I$1, $D18),0) >= 1, TRUE,FALSE) -> TRUE | J18: =IF(IFERROR(SEARCH(J$1, $D18),0) >= 1, TRUE,FALSE) -> TRUE | K18: =IF(IFERROR(SEARCH(K$1, $D18),0) >= 1, TRUE,FALSE) -> TRUE | M18: TRUE | N18: TRUE | O18: FALSE | P18: FALSE | Q18: =IF(ISBLANK(A18),B18,A18) -> Adornesdomein | R18: 10 | S18: FALSE | T18: FALSE
A19: Atlantikwall Raversyde | C19: West-Vlaanderen | D19: Beeldende kunst, Toegepaste kunst en design, Geschiedenis en archeologie, Wetenschap en technologie, Architectuur | E19: =IF(IFERROR(SEARCH(E$1, $D19),0) >= 1, TRUE,FALSE) -> TRUE | F19: =IF(IFERROR(SEARCH(F$1, $D19),0) >= 1, TRUE,FALSE) -> TRUE | G19: =IF(IFERROR(SEARCH(G$1, $D19),0) >= 1, TRUE,FALSE) -> FALSE | H19: =IF(IFERROR(SEARCH(H$1, $D19),0) >= 1, TRUE,FALSE) -> FALSE | I19: =IF(IFERROR(SEARCH(I$1, $D19),0) >= 1, TRUE,FALSE) -> TRUE | J19: =IF(IFERROR(SEARCH(J$1, $D19),0) >= 1, TRUE,FALSE) -> TRUE | K19: =IF(IFERROR(SEARCH(K$1, $D19),0) >= 1, TRUE,FALSE) -> TRUE | M19: TRUE | N19: TRUE | O19: TRUE | P19: TRUE | Q19: =IF(ISBLANK(A19),B19,A19) -> Atlantikwall Raversyde | R19: 10 | S19: FALSE | T19: TRUE | U19: 10
A20: Bakkerijmuseum | B20: Musée de la Boulangerie | C20: West-Vlaanderen | D20: Geschiedenis en archeologie | E20: =IF(IFERROR(SEARCH(E$1, $D20),0) >= 1, TRUE,FALSE) -> TRUE | F20: =IF(IFERROR(SEARCH(F$1, $D20),0) >= 1, TRUE,FALSE) -> FALSE | G20: =IF(IFERROR(SEARCH(G$1, $D20),0) >= 1, TRUE,FALSE) -> FALSE | H20: =IF(IFERROR(SEARCH(H$1, $D20),0) >= 1, TRUE,FALSE) -> FALSE | I20: =IF(IFERROR(SEARCH(I$1, $D20),0) >= 1, TRUE,FALSE) -> FALSE | J20: =IF(IFERROR(SEARCH(J$1, $D20),0) >= 1, TRUE,FALSE) -> FALSE | K20: =IF(IFERROR(SEARCH(K$1, $D20),0) >= 1, TRUE,FALSE) -> FALSE | M20: TRUE | N20: TRUE | O20: TRUE | P20: TRUE | Q20: =IF(ISBLANK(A20),B20,A20) -> Bakkerijmuseum | R20: 8 | S20: FALSE | T20: FALSE
A21: Belfort van Brugge | B21: Beffroi de Bruges | C21: West-Vlaanderen | D21: Geschiedenis en archeologie, Wetenschap en technologie, Architectuur | E21: =IF(IFERROR(SEARCH(E$1, $D21),0) >= 1, TRUE,FALSE) -> TRUE | F21: =IF(IFERROR(SEARCH(F$1, $D21),0) >= 1, TRUE,FALSE) -> TRUE | G21: =IF(IFERROR(SEARCH(G$1, $D21),0) >= 1, TRUE,FALSE) -> FALSE | H21: =IF(IFERROR(SEARCH(H$1, $D21),0) >= 1, TRUE,FALSE) -> FALSE | I21: =IF(IFERROR(SEARCH(I$1, $D21),0) >= 1, TRUE,FALSE) -> TRUE | J21: =IF(IFERROR(SEARCH(J$1, $D21),0) >= 1, TRUE,FALSE) -> FALSE | K21: =IF(IFERROR(SEARCH(K$1, $D21),0) >= 1, TRUE,FALSE) -> FALSE | M21: FALSE | N21: FALSE | O21: FALSE | P21: FALSE | Q21: =IF(ISBLANK(A21),B21,A21) -> Belfort van Brugge | R21: 15 | S21: FALSE | T21: FALSE
A22: Belle Epoque Centrum | B22: Centre Belle Epoque | C22: West-Vlaanderen | D22: Geschiedenis en archeologie | E22: =IF(IFERROR(SEARCH(E$1, $D22),0) >= 1, TRUE,FALSE) -> TRUE | F22: =IF(IFERROR(SEARCH(F$1, $D22),0) >= 1, TRUE,FALSE) -> FALSE | G22: =IF(IFERROR(SEARCH(G$1, $D22),0) >= 1, TRUE,FALSE) -> FALSE | H22: =IF(IFERROR(SEARCH(H$1, $D22),0) >= 1, TRUE,FALSE) -> FALSE | I22: =IF(IFERROR(SEARCH(I$1, $D22),0) >= 1, TRUE,FALSE) -> FALSE | J22: =IF(IFERROR(SEARCH(J$1, $D22),0) >= 1, TRUE,FALSE) -> FALSE | K22: =IF(IFERROR(SEARCH(K$1, $D22),0) >= 1, TRUE,FALSE) -> FALSE | M22: TRUE | N22: FALSE | O22: FALSE | P22: FALSE | Q22: =IF(ISBLANK(A22),B22,A22) -> Belle Epoque Centrum | R22: 5 | S22: FALSE | T22: FALSE
A23: Brugse Vrije | B23: Franc de Bruges | C23: West-Vlaanderen | D23: Beeldende kunst, Toegepaste kunst en design, Geschiedenis en archeologie | E23: =IF(IFERROR(SEARCH(E$1, $D23),0) >= 1, TRUE,FALSE) -> TRUE | F23: =IF(IFERROR(SEARCH(F$1, $D23),0) >= 1, TRUE,FALSE) -> FALSE | G23: =IF(IFERROR(SEARCH(G$1, $D23),0) >= 1, TRUE,FALSE) -> FALSE | H23: =IF(IFERROR(SEARCH(H$1, $D23),0) >= 1, TRUE,FALSE) -> FALSE | I23: =IF(IFERROR(SEARCH(I$1, $D23),0) >= 1, TRUE,FALSE) -> FALSE | J23: =IF(IFERROR(SEARCH(J$1, $D23),0) >= 1, TRUE,FALSE) -> TRUE | K23: =IF(IFERROR(SEARCH(K$1, $D23),0) >= 1, TRUE,FALSE) -> TRUE | M23: FALSE | N23: FALSE | O23: FALSE | P23: FALSE | Q23: =IF(ISBLANK(A23),B23,A23) -> Brugse Vrije | R23: 3 | S23: FALSE | T23: FALSE
A24: Dodengang | B24: Boyau de la Mort | C24: West-Vlaanderen | D24: Geschiedenis en archeologie | E24: =IF(IFERROR(SEARCH(E$1, $D24),0) >= 1, TRUE,FALSE) -> TRUE | F24: =IF(IFERROR(SEARCH(F$1, $D24),0) >= 1, TRUE,FALSE) -> FALSE | G24: =IF(IFERROR(SEARCH(G$1, $D24),0) >= 1, TRUE,FALSE) -> FALSE | H24: =IF(IFERROR(SEARCH(H$1, $D24),0) >= 1, TRUE,FALSE) -> FALSE | I24: =IF(IFERROR(SEARCH(I$1, $D24),0) >= 1, TRUE,FALSE) -> FALSE | J24: =IF(IFERROR(SEARCH(J$1, $D24),0) >= 1, TRUE,FALSE) -> FALSE | K24: =IF(IFERROR(SEARCH(K$1, $D24),0) >= 1, TRUE,FALSE) -> FALSE | M24: FALSE | N24: FALSE | O24: TRUE | P24: FALSE | Q24: =IF(ISBLANK(A24),B24,A24) -> Dodengang | R24: 6 | S24: FALSE | T24: FALSE
B25: Eperon d’Or | C25: West-Vlaanderen | D25: Geschiedenis en archeologie, Wetenschap en technologie, Architectuur, Mode | E25: =IF(IFERROR(SEARCH(E$1, $D25),0) >= 1, TRUE,FALSE) -> TRUE | F25: =IF(IFERROR(SEARCH(F$1, $D25),0) >= 1, TRUE,FALSE) -> TRUE | G25: =IF(IFERROR(SEARCH(G$1, $D25),0) >= 1, TRUE,FALSE) -> TRUE | H25: =IF(IFERROR(SEARCH(H$1, $D25),0) >= 1, TRUE,FALSE) -> FALSE | I25: =IF(IFERROR(SEARCH(I$1, $D25),0) >= 1, TRUE,FALSE) -> TRUE | J25: =IF(IFERROR(SEARCH(J$1, $D25),0) >= 1, TRUE,FALSE) -> FALSE | K25: =IF(IFERROR(SEARCH(K$1, $D25),0) >= 1, TRUE,FALSE) -> FALSE | M25: TRUE | N25: FALSE | O25: TRUE | P25: FALSE | Q25: =IF(ISBLANK(A25),B25,A25) -> Eperon d’Or | R25: 8 | S25: FALSE | T25: TRUE | U25: 8
A26: Gezellehuis | B26: Maison Gezelle | C26: West-Vlaanderen | D26: Literatuur | E26: =IF(IFERROR(SEARCH(E$1, $D26),0) >= 1, TRUE,FALSE) -> FALSE | F26: =IF(IFERROR(SEARCH(F$1, $D26),0) >= 1, TRUE,FALSE) -> FALSE | G26: =IF(IFERROR(SEARCH(G$1, $D26),0) >= 1, TRUE,FALSE) -> FALSE | H26: =IF(IFERROR(SEARCH(H$1, $D26),0) >= 1, TRUE,FALSE) -> TRUE | I26: =IF(IFERROR(SEARCH(I$1, $D26),0) >= 1, TRUE,FALSE) -> FALSE | J26: =IF(IFERROR(SEARCH(J$1, $D26),0) >= 1, TRUE,FALSE) -> FALSE | K26: =IF(IFERROR(SEARCH(K$1, $D26),0) >= 1, TRUE,FALSE) -> FALSE | M26: FALSE | N26: FALSE | O26: FALSE | P26: FALSE | Q26: =IF(ISBLANK(A26),B26,A26) -> Gezellehuis | R26: 0 | S26: FALSE | T26: FALSE
A27: Groeningemuseum | B27: Musée Groeninge | C27: West-Vlaanderen | D27: Beeldende kunst | E27: =IF(IFERROR(SEARCH(E$1, $D27),0) >= 1, TRUE,FALSE) -> FALSE | F27: =IF(IFERROR(SEARCH(F$1, $D27),0) >= 1, TRUE,FALSE) -> FALSE | G27: =IF(IFERROR(SEARCH(G$1, $D27),0) >= 1, TRUE,FALSE) -> FALSE | H27: =IF(IFERROR(SEARCH(H$1, $D27),0) >= 1, TRUE,FALSE) -> FALSE | I27: =IF(IFERROR(SEARCH(I$1, $D27),0) >= 1, TRUE,FALSE) -> FALSE | J27: =IF(IFERROR(SEARCH(J$1, $D27),0) >= 1, TRUE,FALSE) -> TRUE | K27: =IF(IFERROR(SEARCH(K$1, $D27),0) >= 1, TRUE,FALSE) -> FALSE | M27: TRUE | N27: FALSE | O27: FALSE | P27: FALSE | Q27: =IF(ISBLANK(A27),B27,A27) -> Groeningemuseum | R27: 15 | S27: FALSE | T27: FALSE
A28: Gruuthusemuseum | B28: Musée Gruuthuse | C28: West-Vlaanderen | D28: Beeldende kunst, Toegepaste kunst en design, Geschiedenis en archeologie, Architectuur | E28: =IF(IFERROR(SEARCH(E$1, $D28),0) >= 1, TRUE,FALSE) -> TRUE | F28: =IF(IFERROR(SEARCH(F$1, $D28),0) >= 1, TRUE,FALSE) -> FALSE | G28: =IF(IFERROR(SEARCH(G$1, $D28),0) >= 1, TRUE,FALSE) -> FALSE | H28: =IF(IFERROR(SEARCH(H$1, $D28),0) >= 1, TRUE,FALSE) -> FALSE | I28: =IF(IFERROR(SEARCH(I$1, $D28),0) >= 1, TRUE,FALSE) -> TRUE | J28: =IF(IFERROR(SEARCH(J$1, $D28),0) >= 1, TRUE,FALSE) -> TRUE | K28: =IF(IFERROR(SEARCH(K$1, $D28),0) >= 1, TRUE,FALSE) -> TRUE | M28: FALSE | N28: FALSE | O28: FALSE | P28: FALSE | Q28: =IF(ISBLANK(A28),B28,A28) -> Gruuthusemuseum | R28: 15 | S28: FALSE | T28: FALSE
A29: Het James Ensorhuis | B29: La Maison de James Ensor | C29: West-Vlaanderen | D29: Beeldende kunst | E29: =IF(IFERROR(SEARCH(E$1, $D29),0) >= 1, TRUE,FALSE) -> FALSE | F29: =IF(IFERROR(SEARCH(F$1, $D29),0) >= 1, TRUE,FALSE) -> FALSE | G29: =IF(IFERROR(SEARCH(G$1, $D29),0) >= 1, TRUE,FALSE) -> FALSE | H29: =IF(IFERROR(SEARCH(H$1, $D29),0) >= 1, TRUE,FALSE) -> FALSE | I29: =IF(IFERROR(SEARCH(I$1, $D29),0) >= 1, TRUE,FALSE) -> FALSE | J29: =IF(IFERROR(SEARCH(J$1, $D29),0) >= 1, TRUE,FALSE) -> TRUE | K29: =IF(IFERROR(SEARCH(K$1, $D29),0) >= 1, TRUE,FALSE) -> FALSE | M29: TRUE | N29: FALSE | O29: FALSE | P29: FALSE | Q29: =IF(ISBLANK(A29),B29,A29) -> Het James Ensorhuis | R29: 13 | S29: FALSE | T29: TRUE | U29: 13
A30: Het Lijsternest | Streuvelshuis & Schrijversresidentie | C30: West-Vlaanderen | D30: Beeldende kunst, Architectuur, Literatuur | E30: =IF(IFERROR(SEARCH(E$1, $D30),0) >= 1, TRUE,FALSE) -> FALSE | F30: =IF(IFERROR(SEARCH(F$1, $D30),0) >= 1, TRUE,FALSE) -> FALSE | G30: =IF(IFERROR(SEARCH(G$1, $D30),0) >= 1, TRUE,FALSE) -> FALSE | H30: =IF(IFERROR(SEARCH(H$1, $D30),0) >= 1, TRUE,FALSE) -> TRUE | I30: =IF(IFERROR(SEARCH(I$1, $D30),0) >= 1, TRUE,FALSE) -> TRUE | J30: =IF(IFERROR(SEARCH(J$1, $D30),0) >= 1, TRUE,FALSE) -> TRUE | K30: =IF(IFERROR(SEARCH(K$1, $D30),0) >= 1, TRUE,FALSE) -> FALSE | M30: TRUE | N30: FALSE | O30: TRUE | P30: FALSE | Q30: =IF(ISBLANK(A30),B30,A30) -> Het Lijsternest | Streuvelshuis & Schrijversresidentie | R30: 3 | S30: TRUE | T30: FALSE
A31: HEY Museum | C31: West-Vlaanderen | D31: Beeldende kunst, Geschiedenis en archeologie | E31: =IF(IFERROR(SEARCH(E$1, $D31),0) >= 1, TRUE,FALSE) -> TRUE | F31: =IF(IFERROR(SEARCH(F$1, $D31),0) >= 1, TRUE,FALSE) -> FALSE | G31: =IF(IFERROR(SEARCH(G$1, $D31),0) >= 1, TRUE,FALSE) -> FALSE | H31: =IF(IFERROR(SEARCH(H$1, $D31),0) >= 1, TRUE,FALSE) -> FALSE | I31: =IF(IFERROR(SEARCH(I$1, $D31),0) >= 1, TRUE,FALSE) -> FALSE | J31: =IF(IFERROR(SEARCH(J$1, $D31),0) >= 1, TRUE,FALSE) -> TRUE | K31: =IF(IFERROR(SEARCH(K$1, $D31),0) >= 1, TRUE,FALSE) -> FALSE | M31: TRUE | N31: FALSE | O31: FALSE | P31: FALSE | Q31: =IF(ISBLANK(A31),B31,A31) -> HEY Museum | R31: 10 | S31: FALSE | T31: FALSE
A32: Hopmuseum Poperinge | B32: Musée du Houblon Poperinge | C32: West-Vlaanderen | D32: Geschiedenis en archeologie | E32: =IF(IFERROR(SEARCH(E$1, $D32),0) >= 1, TRUE,FALSE) -> TRUE | F32: =IF(IFERROR(SEARCH(F$1, $D32),0) >= 1, TRUE,FALSE) -> FALSE | G32: =IF(IFERROR(SEARCH(G$1, $D32),0) >= 1, TRUE,FALSE) -> FALSE | H32: =IF(IFERROR(SEARCH(H$1, $D32),0) >= 1, TRUE,FALSE) -> FALSE | I32: =IF(IFERROR(SEARCH(I$1, $D32),0) >= 1, TRUE,FALSE) -> FALSE | J32: =IF(IFERROR(SEARCH(J$1, $D32),0) >= 1, TRUE,FALSE) -> FALSE | K32: =IF(IFERROR(SEARCH(K$1, $D32),0) >= 1, TRUE,FALSE) -> FALSE | M32: TRUE | N32: TRUE | O32: FALSE | P32: FALSE | Q32: =IF(ISBLANK(A32),B32,A32) -> Hopmuseum Poperinge | R32: 7 | S32: FALSE | T32: FALSE
A33: In Flanders Fields Museum | B33: Musée In Flanders Fields | C33: West-Vlaanderen | D33: Geschiedenis en archeologie | E33: =IF(IFERROR(SEARCH(E$1, $D33),0) >= 1, TRUE,FALSE) -> TRUE | F33: =IF(IFERROR(SEARCH(F$1, $D33),0) >= 1, TRUE,FALSE) -> FALSE | G33: =IF(IFERROR(SEARCH(G$1, $D33),0) >= 1, TRUE,FALSE) -> FALSE | H33: =IF(IFERROR(SEARCH(H$1, $D33),0) >= 1, TRUE,FALSE) -> FALSE | I33: =IF(IFERROR(SEARCH(I$1, $D33),0) >= 1, TRUE,FALSE) -> FALSE | J33: =IF(IFERROR(SEARCH(J$1, $D33),0) >= 1, TRUE,FALSE) -> FALSE | K33: =IF(IFERROR(SEARCH(K$1, $D33),0) >= 1, TRUE,FALSE) -> FALSE | M33: TRUE | N33: TRUE | O33: FALSE | P33: FALSE | Q33: =IF(ISBLANK(A33),B33,A33) -> In Flanders Fields Museum | R33: 12 | S33: FALSE | T33: TRUE | U33: 12
A34: Kantmuseum Brugge | B34: Musée de la Dentelle Bruges | C34: West-Vlaanderen | D34: Toegepaste kunst en design, Geschiedenis en archeologie, Mode | E34: =IF(IFERROR(SEARCH(E$1, $D34),0) >= 1, TRUE,FALSE) -> TRUE | F34: =IF(IFERROR(SEARCH(F$1, $D34),0) >= 1, TRUE,FALSE) -> FALSE | G34: =IF(IFERROR(SEARCH(G$1, $D34),0) >= 1, TRUE,FALSE) -> TRUE | H34: =IF(IFERROR(SEARCH(H$1, $D34),0) >= 1, TRUE,FALSE) -> FALSE | I34: =IF(IFERROR(SEARCH(I$1, $D34),0) >= 1, TRUE,FALSE) -> FALSE | J34: =IF(IFERROR(SEARCH(J$1, $D34),0) >= 1, TRUE,FALSE) -> FALSE | K34: =IF(IFERROR(SEARCH(K$1, $D34),0) >= 1, TRUE,FALSE) -> TRUE | M34: TRUE | N34: FALSE | O34: FALSE | P34: FALSE | Q34: =IF(ISBLANK(A34),B34,A34) -> Kantmuseum Brugge | R34: 8 | S34: FALSE | T34: FALSE
A35: Kasteel van Loppem | B35: Château de Loppem | C35: West-Vlaanderen | D35: Beeldende kunst, Geschiedenis en archeologie | E35: =IF(IFERROR(SEARCH(E$1, $D35),0) >= 1, TRUE,FALSE) -> TRUE | F35: =IF(IFERROR(SEARCH(F$1, $D35),0) >= 1, TRUE,FALSE) -> FALSE | G35: =IF(IFERROR(SEARCH(G$1, $D35),0) >= 1, TRUE,FALSE) -> FALSE | H35: =IF(IFERROR(SEARCH(H$1, $D35),0) >= 1, TRUE,FALSE) -> FALSE | I35: =IF(IFERROR(SEARCH(I$1, $D35),0) >= 1, TRUE,FALSE) -> FALSE | J35: =IF(IFERROR(SEARCH(J$1, $D35),0) >= 1, TRUE,FALSE) -> TRUE | K35: =IF(IFERROR(SEARCH(K$1, $D35),0) >= 1, TRUE,FALSE) -> FALSE | M35: TRUE | N35: FALSE | O35: TRUE | P35: FALSE | Q35: =IF(ISBLANK(A35),B35,A35) -> Kasteel van Loppem | R35: 9 | S35: FALSE | T35: FALSE
A36: KOERS | Museum van de Wielersport | B36: Musée de la Course Cycliste | C36: West-Vlaanderen | D36: Geschiedenis en archeologie, Wetenschap en technologie | E36: =IF(IFERROR(SEARCH(E$1, $D36),0) >= 1, TRUE,FALSE) -> TRUE | F36: =IF(IFERROR(SEARCH(F$1, $D36),0) >= 1, TRUE,FALSE) -> TRUE | G36: =IF(IFERROR(SEARCH(G$1, $D36),0) >= 1, TRUE,FALSE) -> FALSE | H36: =IF(IFERROR(SEARCH(H$1, $D36),0) >= 1, TRUE,FALSE) -> FALSE | I36: =IF(IFERROR(SEARCH(I$1, $D36),0) >= 1, TRUE,FALSE) -> FALSE | J36: =IF(IFERROR(SEARCH(J$1, $D36),0) >= 1, TRUE,FALSE) -> FALSE | K36: =IF(IFERROR(SEARCH(K$1, $D36),0) >= 1, TRUE,FALSE) -> FALSE | M36: TRUE | N36: TRUE | O36: FALSE | P36: TRUE | Q36: =IF(ISBLANK(A36),B36,A36) -> KOERS | Museum van de Wielersport | R36: 9 | S36: FALSE | T36: FALSE
A37: Museum aan de IJzer | B37: Musée la tour de L’Yser | C37: West-Vlaanderen | D37: Geschiedenis en archeologie | E37: =IF(IFERROR(SEARCH(E$1, $D37),0) >= 1, TRUE,FALSE) -> TRUE | F37: =IF(IFERROR(SEARCH(F$1, $D37),0) >= 1, TRUE,FALSE) -> FALSE | G37: =IF(IFERROR(SEARCH(G$1, $D37),0) >= 1, TRUE,FALSE) -> FALSE | H37: =IF(IFERROR(SEARCH(H$1, $D37),0) >= 1, TRUE,FALSE) -> FALSE | I37: =IF(IFERROR(SEARCH(I$1, $D37),0) >= 1, TRUE,FALSE) -> FALSE | J37: =IF(IFERROR(SEARCH(J$1, $D37),0) >= 1, TRUE,FALSE) -> FALSE | K37: =IF(IFERROR(SEARCH(K$1, $D37),0) >= 1, TRUE,FALSE) -> FALSE | M37: TRUE | N37: TRUE | O37: TRUE | P37: FALSE | Q37: =IF(ISBLANK(A37),B37,A37) -> Museum aan de IJzer | R37: 9.5 | S37: FALSE | T37: TRUE | U37: 9.5
A38: Museum Sint-Janshospitaal | B38: Musée Hôpital Saint-Jean | C38: West-Vlaanderen | D38: Beeldende kunst, Toegepaste kunst en design, Geschiedenis en archeologie, Wetenschap en technologie, Architectuur | E38: =IF(IFERROR(SEARCH(E$1, $D38),0) >= 1, TRUE,FALSE) -> TRUE | F38: =IF(IFERROR(SEARCH(F$1, $D38),0) >= 1, TRUE,FALSE) -> TRUE | G38: =IF(IFERROR(SEARCH(G$1, $D38),0) >= 1, TRUE,FALSE) -> FALSE | H38: =IF(IFERROR(SEARCH(H$1, $D38),0) >= 1, TRUE,FALSE) -> FALSE | I38: =IF(IFERROR(SEARCH(I$1, $D38),0) >= 1, TRUE,FALSE) -> TRUE | J38: =IF(IFERROR(SEARCH(J$1, $D38),0) >= 1, TRUE,FALSE) -> TRUE | K38: =IF(IFERROR(SEARCH(K$1, $D38),0) >= 1, TRUE,FALSE) -> TRUE | M38: TRUE | N38: FALSE | O38: FALSE | P38: FALSE | Q38: =IF(ISBLANK(A38),B38,A38) -> Museum Sint-Janshospitaal | R38: 15 | S38: FALSE | T38: TRUE | U38: 15
